Workbook

Sheet Samenvatting
A1: Cashflow Uyar Web & Trade
A2: Revolut Business | periode 10 mei t/m 24 juni 2026 | alle bedragen in EUR
A4: Totaal binnengekomen (alle inkomsten) | B4: =SUM(Transacties!L:L)
A5: waarvan omzet (Stripe + Mollie) | B5: =SUMIF(Transacties!H:H,"Omzet",Transacties!L:L)
A6: waarvan eigen inleg (jij stort terug) | B6: =SUMIF(Transacties!H:H,"Eigen inleg",Transacties!L:L)
A8: Totaal eruit (alle uitgaven) | B8: =SUM(Transacties!K:K)
A9: waarvan zakelijk | B9: =SUMIF(Transacties!I:I,"Zakelijk",Transacties!K:K)
A10: waarvan prive (door jou te dragen) | B10: =SUMIF(Transacties!I:I,"Prive",Transacties!K:K)
A12: Netto kasstroom (in - uit) | B12: =B4-B8
A14: PRIVE TERUG TE BETALEN AAN HET BEDRIJF
A15: Prive uitgaven + opnames van zakelijke rekening | B15: =SUMIF(Transacties!I:I,"Prive",Transacties!K:K)
A16: Al teruggestort (eigen inleg) | B16: =SUMIF(Transacties!H:H,"Eigen inleg",Transacties!L:L)
A17: NOG TERUG TE BETALEN | B17: =B15-B16
A19: Controle met Revolut-statement (moet kloppen):
A20: Statement: Money in 102.382,04 / Money out 93.727,99
A21: Lees tabblad 'Toelichting' voor uitleg + de aannames.

Sheet Transacties
A1: Datum | B1: Week nr | C1: Week-start | D1: Maand | E1: Richting | F1: Omschrijving | G1: Tegenpartij | H1: Categorie | I1: Prive/Zakelijk | J1: Terugbetalen | K1: Bedrag uit (€) | L1: Bedrag in (€) | M1: Origineel (valuta) | N1: Notitie
A2: 46197 | B2: =ISOWEEKNUM(A2) | C2: =A2-WEEKDAY(A2,2)+1 | D2: =TEXT(A2,"mmm yyyy") | E2: Uit | F2: Easyparknlcom | G2: Easypark | H2: Parkeren | I2: Prive | J2: Ja | K2: 3.21
A3: 46197 | B3: =ISOWEEKNUM(A3) | C3: =A3-WEEKDAY(A3,2)+1 | D3: =TEXT(A3,"mmm yyyy") | E3: In | F3: Money added Stripe A5P0M0 | G3: Stripe | H3: Omzet | I3: Zakelijk | J3: Nee | L3: 1182.57
A4: 46196 | B4: =ISOWEEKNUM(A4) | C4: =A4-WEEKDAY(A4,2)+1 | D4: =TEXT(A4,"mmm yyyy") | E4: Uit | F4: Vercel Inc. | G4: Vercel | H4: Software & Tools | I4: Zakelijk | J4: Nee | K4: 21.19 | M4: $24.20
A5: 46196 | B5: =ISOWEEKNUM(A5) | C5: =A5-WEEKDAY(A5,2)+1 | D5: =TEXT(A5,"mmm yyyy") | E5: Uit | F5: Paypal it Service | G5: PayPal | H5: Software & Tools | I5: Zakelijk | J5: Nee | K5: 2.61 | M5: $2.99
A6: 46196 | B6: =ISOWEEKNUM(A6) | C6: =A6-WEEKDAY(A6,2)+1 | D6: =TEXT(A6,"mmm yyyy") | E6: Uit | F6: Commentguard.io | G6: Commentguard | H6: Software & Tools | I6: Zakelijk | J6: Nee | K6: 30.63 | M6: $35.09
A7: 46196 | B7: =ISOWEEKNUM(A7) | C7: =A7-WEEKDAY(A7,2)+1 | D7: =TEXT(A7,"mmm yyyy") | E7: In | F7: Money added Stripe T0T0P4 | G7: Stripe | H7: Omzet | I7: Zakelijk | J7: Nee | L7: 1684.8
A8: 46196 | B8: =ISOWEEKNUM(A8) | C8: =A8-WEEKDAY(A8,2)+1 | D8: =TEXT(A8,"mmm yyyy") | E8: Uit | F8: To HK Jinchenyun CD000749 | G8: HK Jinchenyun | H8: Voorraad/Leverancier | I8: Zakelijk | J8: Nee | K8: 8000.2 | N8: incl. 0.20 fee
A9: 46196 | B9: =ISOWEEKNUM(A9) | C9: =A9-WEEKDAY(A9,2)+1 | D9: =TEXT(A9,"mmm yyyy") | E9: Uit | F9: To Hiltermann Lease B.V. | G9: Hiltermann Lease | H9: Auto/Lease | I9: Zakelijk | J9: Nee | K9: 1779.5 | N9: Leasecontract - check prive/bijtelling
A10: 46195 | B10: =ISOWEEKNUM(A10) | C10: =A10-WEEKDAY(A10,2)+1 | D10: =TEXT(A10,"mmm yyyy") | E10: Uit | F10: Checkify.pro | G10: Checkify.pro | H10: Software & Tools | I10: Zakelijk | J10: Nee | K10: 37.07
A11: 46195 | B11: =ISOWEEKNUM(A11) | C11: =A11-WEEKDAY(A11,2)+1 | D11: =TEXT(A11,"mmm yyyy") | E11: Uit | F11: Easyparknlcom | G11: Easypark | H11: Parkeren | I11: Prive | J11: Ja | K11: 3.27
A12: 46195 | B12: =ISOWEEKNUM(A12) | C12: =A12-WEEKDAY(A12,2)+1 | D12: =TEXT(A12,"mmm yyyy") | E12: Uit | F12: Apple.com/bill | G12: Apple | H12: Software & Tools | I12: Zakelijk | J12: Nee | K12: 10 | N12: Check prive
A13: 46195 | B13: =ISOWEEKNUM(A13) | C13: =A13-WEEKDAY(A13,2)+1 | D13: =TEXT(A13,"mmm yyyy") | E13: In | F13: Money added Stripe Q8Y0Z5 | G13: Stripe | H13: Omzet | I13: Zakelijk | J13: Nee | L13: 2645.68
A14: 46194 | B14: =ISOWEEKNUM(A14) | C14: =A14-WEEKDAY(A14,2)+1 | D14: =TEXT(A14,"mmm yyyy") | E14: Uit | F14: To CC Ecommerce 0722 | G14: CC Ecommerce Solutions | H14: Voorraad/Leverancier | I14: Zakelijk | J14: Nee | K14: 2600.2 | N14: incl. fee
A15: 46194 | B15: =ISOWEEKNUM(A15) | C15: =A15-WEEKDAY(A15,2)+1 | D15: =TEXT(A15,"mmm yyyy") | E15: Uit | F15: Checkify.pro Subs Fees | G15: Checkify.pro | H15: Software & Tools | I15: Zakelijk | J15: Nee | K15: 50.42
A16: 46194 | B16: =ISOWEEKNUM(A16) | C16: =A16-WEEKDAY(A16,2)+1 | D16: =TEXT(A16,"mmm yyyy") | E16: Uit | F16: Dhgate.com | G16: DHgate | H16: Voorraad/Leverancier | I16: Zakelijk | J16: Nee | K16: 26.61
A17: 46193 | B17: =ISOWEEKNUM(A17) | C17: =A17-WEEKDAY(A17,2)+1 | D17: =TEXT(A17,"mmm yyyy") | E17: Uit | F17: Klaviyo Inc Software | G17: Klaviyo | H17: Software & Tools | I17: Zakelijk | J17: Nee | K17: 26.44 | M17: $30.00
A18: 46193 | B18: =ISOWEEKNUM(A18) | C18: =A18-WEEKDAY(A18,2)+1 | D18: =TEXT(A18,"mmm yyyy") | E18: Uit | F18: Oxylabs | G18: Oxylabs | H18: Software & Tools | I18: Zakelijk | J18: Nee | K18: 31.69 | M18: $36.30
A19: 46193 | B19: =ISOWEEKNUM(A19) | C19: =A19-WEEKDAY(A19,2)+1 | D19: =TEXT(A19,"mmm yyyy") | E19: Uit | F19: Easyparknlcom | G19: Easypark | H19: Parkeren | I19: Prive | J19: Ja | K19: 3.27
A20: 46193 | B20: =ISOWEEKNUM(A20) | C20: =A20-WEEKDAY(A20,2)+1 | D20: =TEXT(A20,"mmm yyyy") | E20: Uit | F20: Makara Amsterdam-west | G20: Makara | H20: Eten & Restaurant | I20: Prive | J20: Ja | K20: 40 | N20: Restaurant
A21: 46193 | B21: =ISOWEEKNUM(A21) | C21: =A21-WEEKDAY(A21,2)+1 | D21: =TEXT(A21,"mmm yyyy") | E21: Uit | F21: Shopify 546518278 | G21: Shopify | H21: Software & Tools | I21: Zakelijk | J21: Nee | K21: 69.67
A22: 46193 | B22: =ISOWEEKNUM(A22) | C22: =A22-WEEKDAY(A22,2)+1 | D22: =TEXT(A22,"mmm yyyy") | E22: Uit | F22: Dm Drogerie Sagt Danke | G22: DM Drogerie | H22: Persoonlijk | I22: Prive | J22: Ja | K22: 24.2 | N22: Drogist (DE)
A23: 46192 | B23: =ISOWEEKNUM(A23) | C23: =A23-WEEKDAY(A23,2)+1 | D23: =TEXT(A23,"mmm yyyy") | E23: Uit | F23: Haus Des Doeners | G23: Haus Des Doeners | H23: Eten & Restaurant | I23: Prive | J23: Ja | K23: 20.5
A24: 46192 | B24: =ISOWEEKNUM(A24) | C24: =A24-WEEKDAY(A24,2)+1 | D24: =TEXT(A24,"mmm yyyy") | E24: Uit | F24: Tamoil Enschede | G24: Tamoil | H24: Brandstof | I24: Prive | J24: Ja | K24: 24.99
A25: 46192 | B25: =ISOWEEKNUM(A25) | C25: =A25-WEEKDAY(A25,2)+1 | D25: =TEXT(A25,"mmm yyyy") | E25: Uit | F25: Bck varo Energy Retail B. | G25: Varo Energy | H25: Brandstof | I25: Prive | J25: Ja | K25: 1
A26: 46192 | B26: =ISOWEEKNUM(A26) | C26: =A26-WEEKDAY(A26,2)+1 | D26: =TEXT(A26,"mmm yyyy") | E26: Uit | F26: Bp De Bolder | G26: Bp De Bolder | H26: Eten & Restaurant | I26: Prive | J26: Ja | K26: 12.02
A27: 46192 | B27: =ISOWEEKNUM(A27) | C27: =A27-WEEKDAY(A27,2)+1 | D27: =TEXT(A27,"mmm yyyy") | E27: Uit | F27: Flughafen Duesseldorf | G27: Flughafen Dusseldorf | H27: Parkeren | I27: Prive | J27: Ja | K27: 8 | N27: Luchthaven (parkeren/reizen)
A28: 46192 | B28: =ISOWEEKNUM(A28) | C28: =A28-WEEKDAY(A28,2)+1 | D28: =TEXT(A28,"mmm yyyy") | E28: Uit | F28: Shell Express Hilversum N | G28: Shell | H28: Brandstof | I28: Prive | J28: Ja | K28: 20.1
A29: 46192 | B29: =ISOWEEKNUM(A29) | C29: =A29-WEEKDAY(A29,2)+1 | D29: =TEXT(A29,"mmm yyyy") | E29: Uit | F29: Cafe Femm | G29: Cafe Femm | H29: Eten & Restaurant | I29: Prive | J29: Ja | K29: 14.9
A30: 46192 | B30: =ISOWEEKNUM(A30) | C30: =A30-WEEKDAY(A30,2)+1 | D30: =TEXT(A30,"mmm yyyy") | E30: Uit | F30: Acs 05854834 Odido | G30: Odido | H30: Telefoon/Communicatie | I30: Zakelijk | J30: Nee | K30: 10 | N30: Telefoon - check prive
A31: 46192 | B31: =ISOWEEKNUM(A31) | C31: =A31-WEEKDAY(A31,2)+1 | D31: =TEXT(A31,"mmm yyyy") | E31: In | F31: Money added Stripe T3H9S1 | G31: Stripe | H31: Omzet | I31: Zakelijk | J31: Nee | L31: 2558.93
A32: 46191 | B32: =ISOWEEKNUM(A32) | C32: =A32-WEEKDAY(A32,2)+1 | D32: =TEXT(A32,"mmm yyyy") | E32: Uit | F32: Esso Maartensdijk Ni | G32: Esso | H32: Brandstof | I32: Prive | J32: Ja | K32: 5
A33: 46191 | B33: =ISOWEEKNUM(A33) | C33: =A33-WEEKDAY(A33,2)+1 | D33: =TEXT(A33,"mmm yyyy") | E33: Uit | F33: Bck roebert Tankstations | G33: Roebert Tankstations | H33: Brandstof | I33: Prive | J33: Ja | K33: 5
A34: 46191 | B34: =ISOWEEKNUM(A34) | C34: =A34-WEEKDAY(A34,2)+1 | D34: =TEXT(A34,"mmm yyyy") | E34: Uit | F34: Mm Leidsche Rijn | G34: MM Leidsche Rijn | H34: Boodschappen | I34: Prive | J34: Ja | K34: 32.89 | N34: Verifieer
A35: 46191 | B35: =ISOWEEKNUM(A35) | C35: =A35-WEEKDAY(A35,2)+1 | D35: =TEXT(A35,"mmm yyyy") | E35: Uit | F35: Easyparknlcom | G35: Easypark | H35: Parkeren | I35: Prive | J35: Ja | K35: 1.66
A36: 46191 | B36: =ISOWEEKNUM(A36) | C36: =A36-WEEKDAY(A36,2)+1 | D36: =TEXT(A36,"mmm yyyy") | E36: Uit | F36: To Talat Uyar Prive | G36: Talat (prive) | H36: Prive-opname | I36: Prive | J36: Ja | K36: 166
A37: 46191 | B37: =ISOWEEKNUM(A37) | C37: =A37-WEEKDAY(A37,2)+1 | D37: =TEXT(A37,"mmm yyyy") | E37: In | F37: Money added Stripe S4J5K4 | G37: Stripe | H37: Omzet | I37: Zakelijk | J37: Nee | L37: 8812.14
A38: 46191 | B38: =ISOWEEKNUM(A38) | C38: =A38-WEEKDAY(A38,2)+1 | D38: =TEXT(A38,"mmm yyyy") | E38: Uit | F38: To Goatly VITAL NAD+ via Stripe | G38: Goatly | H38: Overig | I38: Zakelijk | J38: Nee | K38: 23.97 | N38: Goatly/NAD+ - verifieer
A39: 46190 | B39: =ISOWEEKNUM(A39) | C39: =A39-WEEKDAY(A39,2)+1 | D39: =TEXT(A39,"mmm yyyy") | E39: Uit | F39: Railway | G39: Railway | H39: Software & Tools | I39: Zakelijk | J39: Nee | K39: 4.31 | M39: $5.00 | N39: Hosting/infra
A40: 46190 | B40: =ISOWEEKNUM(A40) | C40: =A40-WEEKDAY(A40,2)+1 | D40: =TEXT(A40,"mmm yyyy") | E40: Uit | F40: Albert Heijn 1155 | G40: Albert Heijn | H40: Boodschappen | I40: Prive | J40: Ja | K40: 12.4
...

Sheet Weekoverzicht
A1: Week | B1: Van (maandag) | C1: Inkomsten | D1: Uitgaven (totaal) | E1: waarvan zakelijk | F1: waarvan prive | G1: Netto
A2: Wk 20 | B2: 46153 | C2: =SUMIFS(Transacties!L:L,Transacties!C:C,B2) | D2: =SUMIFS(Transacties!K:K,Transacties!C:C,B2) | E2: =SUMIFS(Transacties!K:K,Transacties!C:C,B2,Transacties!I:I,"Zakelijk") | F2: =SUMIFS(Transacties!K:K,Transacties!C:C,B2,Transacties!I:I,"Prive") | G2: =C2-D2
A3: Wk 21 | B3: 46160 | C3: =SUMIFS(Transacties!L:L,Transacties!C:C,B3) | D3: =SUMIFS(Transacties!K:K,Transacties!C:C,B3) | E3: =SUMIFS(Transacties!K:K,Transacties!C:C,B3,Transacties!I:I,"Zakelijk") | F3: =SUMIFS(Transacties!K:K,Transacties!C:C,B3,Transacties!I:I,"Prive") | G3: =C3-D3
A4: Wk 22 | B4: 46167 | C4: =SUMIFS(Transacties!L:L,Transacties!C:C,B4) | D4: =SUMIFS(Transacties!K:K,Transacties!C:C,B4) | E4: =SUMIFS(Transacties!K:K,Transacties!C:C,B4,Transacties!I:I,"Zakelijk") | F4: =SUMIFS(Transacties!K:K,Transacties!C:C,B4,Transacties!I:I,"Prive") | G4: =C4-D4
A5: Wk 23 | B5: 46174 | C5: =SUMIFS(Transacties!L:L,Transacties!C:C,B5) | D5: =SUMIFS(Transacties!K:K,Transacties!C:C,B5) | E5: =SUMIFS(Transacties!K:K,Transacties!C:C,B5,Transacties!I:I,"Zakelijk") | F5: =SUMIFS(Transacties!K:K,Transacties!C:C,B5,Transacties!I:I,"Prive") | G5: =C5-D5
A6: Wk 24 | B6: 46181 | C6: =SUMIFS(Transacties!L:L,Transacties!C:C,B6) | D6: =SUMIFS(Transacties!K:K,Transacties!C:C,B6) | E6: =SUMIFS(Transacties!K:K,Transacties!C:C,B6,Transacties!I:I,"Zakelijk") | F6: =SUMIFS(Transacties!K:K,Transacties!C:C,B6,Transacties!I:I,"Prive") | G6: =C6-D6
A7: Wk 25 | B7: 46188 | C7: =SUMIFS(Transacties!L:L,Transacties!C:C,B7) | D7: =SUMIFS(Transacties!K:K,Transacties!C:C,B7) | E7: =SUMIFS(Transacties!K:K,Transacties!C:C,B7,Transacties!I:I,"Zakelijk") | F7: =SUMIFS(Transacties!K:K,Transacties!C:C,B7,Transacties!I:I,"Prive") | G7: =C7-D7
A8: Wk 26 | B8: 46195 | C8: =SUMIFS(Transacties!L:L,Transacties!C:C,B8) | D8: =SUMIFS(Transacties!K:K,Transacties!C:C,B8) | E8: =SUMIFS(Transacties!K:K,Transacties!C:C,B8,Transacties!I:I,"Zakelijk") | F8: =SUMIFS(Transacties!K:K,Transacties!C:C,B8,Transacties!I:I,"Prive") | G8: =C8-D8
A9: TOTAAL | C9: =SUM(C2:C8) | D9: =SUM(D2:D8) | E9: =SUM(E2:E8) | F9: =SUM(F2:F8) | G9: =SUM(G2:G8)

Sheet Categorieen
A1: Categorie | B1: Uitgaven (€) | C1: Inkomsten (€)
A2: Omzet | B2: =SUMIF(Transacties!H:H,A2,Transacties!K:K) | C2: =SUMIF(Transacties!H:H,A2,Transacties!L:L)
A3: Eigen inleg | B3: =SUMIF(Transacties!H:H,A3,Transacties!K:K) | C3: =SUMIF(Transacties!H:H,A3,Transacties!L:L)
A4: Voorraad/Leverancier | B4: =SUMIF(Transacties!H:H,A4,Transacties!K:K) | C4: =SUMIF(Transacties!H:H,A4,Transacties!L:L)
A5: Software & Tools | B5: =SUMIF(Transacties!H:H,A5,Transacties!K:K) | C5: =SUMIF(Transacties!H:H,A5,Transacties!L:L)
A6: Auto/Lease | B6: =SUMIF(Transacties!H:H,A6,Transacties!K:K) | C6: =SUMIF(Transacties!H:H,A6,Transacties!L:L)
A7: Brandstof | B7: =SUMIF(Transacties!H:H,A7,Transacties!K:K) | C7: =SUMIF(Transacties!H:H,A7,Transacties!L:L)
A8: Parkeren | B8: =SUMIF(Transacties!H:H,A8,Transacties!K:K) | C8: =SUMIF(Transacties!H:H,A8,Transacties!L:L)
A9: Boodschappen | B9: =SUMIF(Transacties!H:H,A9,Transacties!K:K) | C9: =SUMIF(Transacties!H:H,A9,Transacties!L:L)
A10: Eten & Restaurant | B10: =SUMIF(Transacties!H:H,A10,Transacties!K:K) | C10: =SUMIF(Transacties!H:H,A10,Transacties!L:L)
A11: Kleding | B11: =SUMIF(Transacties!H:H,A11,Transacties!K:K) | C11: =SUMIF(Transacties!H:H,A11,Transacties!L:L)
A12: Persoonlijk | B12: =SUMIF(Transacties!H:H,A12,Transacties!K:K) | C12: =SUMIF(Transacties!H:H,A12,Transacties!L:L)
A13: Crypto | B13: =SUMIF(Transacties!H:H,A13,Transacties!K:K) | C13: =SUMIF(Transacties!H:H,A13,Transacties!L:L)
... A17: Overig | B17: =SUMIF(Transacties!H:H,A17,Transacties!K:K) | C17: =SUMIF(Transacties!H:H,A17,Transacties!L:L)
A18: TOTAAL | B18: =SUM(B2:B17) | C18: =SUM(C2:C17)

Sheet Prive terugbetalen
A1: Prive terug te betalen aan het bedrijf
A2: Alles wat je prive met de zakelijke rekening betaalde (incl. brandstof + parkeren), plus opnames. Eigen inleg = al terugbetaald.
A4: Prive uitgaven + opnames (totaal) | B4: =SUMIF(Transacties!I:I,"Prive",Transacties!K:K)
A5: Al teruggestort (eigen inleg) | B5: =SUMIF(Transacties!H:H,"Eigen inleg",Transacties!L:L)
A6: NOG TERUG TE BETALEN | B6: =B4-B5
A8: Uitsplitsing prive per categorie
A9: Categorie | B9: Bedrag (€)
A10: Brandstof | B10: =SUMIFS(Transacties!K:K,Transacties!H:H,A10,Transacties!I:I,"Prive")
A11: Parkeren | B11: =SUMIFS(Transacties!K:K,Transacties!H:H,A11,Transacties!I:I,"Prive")
A12: Boodschappen | B12: =SUMIFS(Transacties!K:K,Transacties!H:H,A12,Transacties!I:I,"Prive")
A13: Eten & Restaurant | B13: =SUMIFS(Transacties!K:K,Transacties!H:H,A13,Transacties!I:I,"Prive")
A14: Kleding | B14: =SUMIFS(Transacties!K:K,Transacties!H:H,A14,Transacties!I:I,"Prive")
A15: Persoonlijk | B15: =SUMIFS(Transacties!K:K,Transacties!H:H,A15,Transacties!I:I,"Prive")
A16: Crypto | B16: =SUMIFS(Transacties!K:K,Transacties!H:H,A16,Transacties!I:I,"Prive")
A17: Auto/Lease | B17: =SUMIFS(Transacties!K:K,Transacties!H:H,A17,Transacties!I:I,"Prive")
A18: Prive-opname | B18: =SUMIFS(Transacties!K:K,Transacties!H:H,A18,Transacties!I:I,"Prive")
A19: Overig | B19: =SUMIFS(Transacties!K:K,Transacties!H:H,A19,Transacties!I:I,"Prive")
A20: TOTAAL prive | B20: =SUM(B10:B19)

Sheet Toelichting
A1: Cashflow-sheet Uyar Web & Trade — uitleg
A3: Wat dit is:
A4: Alle transacties op je Revolut Business rekening, 10 mei t/m 24 juni 2026 (Revolut account statement).
A5: Roze regel = prive, groene regel = geld erin. Klik de filterknoppen in de kop van 'Transacties' om te sorteren/filteren.
A7: De tabbladen:
A8: - Samenvatting: totalen + hoeveel je nog prive moet terugbetalen + controle tegen het Revolut-statement.
A9: - Transacties: alle regels met dropdowns (Categorie / Prive-Zakelijk / Terugbetalen).
A10: - Weekoverzicht: per week in / uit / netto, zakelijk vs prive (wk 20 t/m 26).
A11: - Categorieen: totaal per categorie.
A12: - Prive terugbetalen: wat je prive gebruikte minus je inleg.
A14: Wijziging t.o.v. vorige versie:
A15: Brandstof EN parkeren staan nu op PRIVE (jouw instructie). Ze tellen dus mee in 'nog terug te betalen'.
... A18: Prive uitgaven met de zakelijke kaart (boodschappen, eten, kleding, brandstof, parkeren, crypto) + opnames naar prive
A19: ='prive gebruikt'. Stortingen 'From Talat U' = 'eigen inleg' en halen dat van je schuld af.
A20: NOG TERUG TE BETALEN = prive gebruikt - eigen inleg. Dit is je rekening-courant met de zaak (check met boekhouder).
A22: Aannames (pas aan in kolom 'Prive/Zakelijk' als het anders is):
A23: - PRIVE: boodschappen, eten/restaurant, kleding, kapper, Kindle, Patreon, brandstof, parkeren, crypto (Moonpay).
A24: - ZAKELIJK: software/tools, leveranciers (CC Ecommerce, HK Jinchenyun, DHgate), bankkosten, telefoon.
A25: - Hiltermann Lease B.V. (1.779,50) = autolease, op ZAKELIJK gezet met de melding 'check prive/bijtelling'. Beoordeel zelf.
A26: - 'To Goatly VITAL NAD+' (23,97), Stichting Pair Finance (257), PayPal, 'To Koc via Tikkie', Merkala, MM Leidsche Rijn,
A27: Odido: gemarkeerd 'verifieer' in de notitie. Crypto staat op prive maar verifieer of het zakelijk is.
A29: Controle:
A30: Totaal uitgaven hoort 93.727,99 te zijn en inkomsten 102.382,04 (staat in het Revolut-statement). Klopt in de Samenvatting.
A32: Nieuwe maand toevoegen:
A33: Plak nieuwe regels onder in 'Transacties'. Datum + bedrag uit OF in invullen, dropdowns kiezen. Kolommen Week, Week-start
A34: en Maand vullen zichzelf (kopieer de formules mee uit de regel erboven). Alle totalen rekenen automatisch door.
A36: Grootste post: 'To CC Ecommerce Solutions 0722' (leverancier, dagelijks duizenden euro). Check tegen je inkoopfacturen.
